<?xml version='1.0'?>
<sdf version='1.7'>
  <model name='robot'>
    <link name='base_link'>
      <inertial>
        <pose>0 0 0 0 -0 0</pose>
        <mass>262.098</mass>
        <inertia>
          <ixx>0.067866</ixx>
          <ixy>0</ixy>
          <ixz>0</ixz>
          <iyy>0.067886</iyy>
          <iyz>0</iyz>
          <izz>0.131532</izz>
        </inertia>
      </inertial>
      <collision name='base_link_collision'>
        <pose>0 0 0 0 -0 0</pose>
        <geometry>
          <mesh>
            <scale>1 1 1</scale>
            <uri>/home/jgy/RMUC_simulation/src/sentry_simulation/mesh/omni/base.stl</uri>
          </mesh>
        </geometry>
        <surface>
          <contact>
            <ode/>
          </contact>
          <friction>
            <ode/>
            <torsional>
              <ode/>
            </torsional>
          </friction>
          <bounce/>
        </surface>
        <max_contacts>10</max_contacts>
      </collision>
      <visual name='base_link_visual'>
        <pose>0 0 0 0 -0 0</pose>
        <geometry>
          <mesh>
            <scale>1 1 1</scale>
            <uri>/home/jgy/RMUC_simulation/src/sentry_simulation/mesh/omni/base.stl</uri>
          </mesh>
        </geometry>
        <material>
          <script>
            <name>Gazebo/White</name>
            <uri>file://media/materials/scripts/gazebo.material</uri>
          </script>
        </material>
      </visual>
      <pose>0 0 0 0 -0 0</pose>
      <self_collide>0</self_collide>
      <enable_wind>0</enable_wind>
      <kinematic>0</kinematic>
    </link>
    <joint name='left_wheel_joint' type='revolute'>
      <pose relative_to='base_link'>-0.034641 0.02 0 1.5708 -0 1.0472</pose>
      <parent>base_link</parent>
      <child>left_wheel_link</child>
      <axis>
        <xyz>0 0 1</xyz>
        <limit>
          <lower>-1e+16</lower>
          <upper>1e+16</upper>
        </limit>
        <dynamics>
          <spring_reference>0</spring_reference>
          <spring_stiffness>0</spring_stiffness>
        </dynamics>
      </axis>
    </joint>
    <link name='left_wheel_link'>
      <pose relative_to='left_wheel_joint'>0 0 0 0 -0 0</pose>
      <inertial>
        <pose>0 0 -0.000343 0 -0 0</pose>
        <mass>41.7879</mass>
        <inertia>
          <ixx>0.00331842</ixx>
          <ixy>0</ixy>
          <ixz>0</ixz>
          <iyy>0.00331842</iyy>
          <iyz>0</iyz>
          <izz>0.00470166</izz>
        </inertia>
      </inertial>
      <collision name='left_wheel_link_collision'>
        <pose>0 0 0 0 -0 0</pose>
        <geometry>
          <mesh>
            <scale>1 1 1</scale>
            <uri>/home/jgy/RMUC_simulation/src/sentry_simulation/mesh/omni/wheel.stl</uri>
          </mesh>
        </geometry>
        <surface>
          <contact>
            <ode/>
          </contact>
          <friction>
            <ode/>
            <torsional>
              <ode/>
            </torsional>
          </friction>
          <bounce/>
        </surface>
        <max_contacts>10</max_contacts>
      </collision>
      <visual name='left_wheel_link_visual'>
        <pose>0 0 0 0 -0 0</pose>
        <geometry>
          <mesh>
            <scale>1 1 1</scale>
            <uri>/home/jgy/RMUC_simulation/src/sentry_simulation/mesh/omni/wheel.stl</uri>
          </mesh>
        </geometry>
        <material>
          <script>
            <name>Gazebo/Red</name>
            <uri>file://media/materials/scripts/gazebo.material</uri>
          </script>
        </material>
      </visual>
      <pose>0 0 0 0 -0 0</pose>
      <self_collide>0</self_collide>
      <enable_wind>0</enable_wind>
      <kinematic>0</kinematic>
    </link>
    <joint name='left_roller_e_joint' type='revolute'>
      <pose relative_to='left_wheel_link'>0.01355 0 0.0055 -1.5708 0 0</pose>
      <parent>left_wheel_link</parent>
      <child>left_roller_e_link</child>
      <axis>
        <xyz>0 0 1</xyz>
        <limit>
          <lower>-1e+16</lower>
          <upper>1e+16</upper>
        </limit>
        <dynamics>
          <spring_reference>0</spring_reference>
          <spring_stiffness>0</spring_stiffness>
        </dynamics>
      </axis>
    </joint>
    <link name='left_roller_e_link'>
      <pose relative_to='left_roller_e_joint'>0 0 0 0 -0 0</pose>
      <inertial>
        <pose>0 0 0 0 -0 0</pose>
        <mass>3.7948</mass>
        <inertia>
          <ixx>8.4592e-05</ixx>
          <ixy>0</ixy>
          <ixz>0</ixz>
          <iyy>8.4592e-05</iyy>
          <iyz>0</iyz>
          <izz>4.9222e-05</izz>
        </inertia>
      </inertial>
      <collision name='left_roller_e_link_collision'>
        <pose>0 0 0 0 -0 0</pose>
        <geometry>
          <mesh>
            <scale>1 1 1</scale>
            <uri>/home/jgy/RMUC_simulation/src/sentry_simulation/mesh/omni/roller.stl</uri>
          </mesh>
        </geometry>
        <surface>
          <contact>
            <ode/>
          </contact>
          <friction>
            <ode/>
            <torsional>
              <ode/>
            </torsional>
          </friction>
          <bounce/>
        </surface>
        <max_contacts>10</max_contacts>
      </collision>
      <visual name='left_roller_e_link_visual'>
        <pose>0 0 0 0 -0 0</pose>
        <geometry>
          <mesh>
            <scale>1 1 1</scale>
            <uri>/home/jgy/RMUC_simulation/src/sentry_simulation/mesh/omni/roller.stl</uri>
          </mesh>
        </geometry>
        <material>
          <script>
            <name>Gazebo/Black</name>
            <uri>file://media/materials/scripts/gazebo.material</uri>
          </script>
        </material>
      </visual>
      <pose>0 0 0 0 -0 0</pose>
      <self_collide>0</self_collide>
      <enable_wind>0</enable_wind>
      <kinematic>0</kinematic>
    </link>
    <joint name='left_roller_n_joint' type='revolute'>
      <pose relative_to='left_wheel_link'>0 0.01355 0.0055 -1.5708 0 1.5708</pose>
      <parent>left_wheel_link</parent>
      <child>left_roller_n_link</child>
      <axis>
        <xyz>0 0 1</xyz>
        <limit>
          <lower>-1e+16</lower>
          <upper>1e+16</upper>
        </limit>
        <dynamics>
          <spring_reference>0</spring_reference>
          <spring_stiffness>0</spring_stiffness>
        </dynamics>
      </axis>
    </joint>
    <link name='left_roller_n_link'>
      <pose relative_to='left_roller_n_joint'>0 0 0 0 -0 0</pose>
      <inertial>
        <pose>0 0 0 0 -0 0</pose>
        <mass>3.7948</mass>
        <inertia>
          <ixx>8.4592e-05</ixx>
          <ixy>0</ixy>
          <ixz>0</ixz>
          <iyy>8.4592e-05</iyy>
          <iyz>0</iyz>
          <izz>4.9222e-05</izz>
        </inertia>
      </inertial>
      <collision name='left_roller_n_link_collision'>
        <pose>0 0 0 0 -0 0</pose>
        <geometry>
          <mesh>
            <scale>1 1 1</scale>
            <uri>/home/jgy/RMUC_simulation/src/sentry_simulation/mesh/omni/roller.stl</uri>
          </mesh>
        </geometry>
        <surface>
          <contact>
            <ode/>
          </contact>
          <friction>
            <ode/>
            <torsional>
              <ode/>
            </torsional>
          </friction>
          <bounce/>
        </surface>
        <max_contacts>10</max_contacts>
      </collision>
      <visual name='left_roller_n_link_visual'>
        <pose>0 0 0 0 -0 0</pose>
        <geometry>
          <mesh>
            <scale>1 1 1</scale>
            <uri>/home/jgy/RMUC_simulation/src/sentry_simulation/mesh/omni/roller.stl</uri>
          </mesh>
        </geometry>
        <material>
          <script>
            <name>Gazebo/Black</name>
            <uri>file://media/materials/scripts/gazebo.material</uri>
          </script>
        </material>
      </visual>
      <pose>0 0 0 0 -0 0</pose>
      <self_collide>0</self_collide>
      <enable_wind>0</enable_wind>
      <kinematic>0</kinematic>
    </link>
    <joint name='left_roller_ne_joint' type='revolute'>
      <pose relative_to='left_wheel_link'>0.009581 0.009581 -0.0055 -1.5708 -0 0.785398</pose>
      <parent>left_wheel_link</parent>
      <child>left_roller_ne_link</child>
      <axis>
        <xyz>0 0 1</xyz>
        <limit>
          <lower>-1e+16</lower>
          <upper>1e+16</upper>
        </limit>
        <dynamics>
          <spring_reference>0</spring_reference>
          <spring_stiffness>0</spring_stiffness>
        </dynamics>
      </axis>
    </joint>
    <link name='left_roller_ne_link'>
      <pose relative_to='left_roller_ne_joint'>0 0 0 0 -0 0</pose>
      <inertial>
        <pose>0 0 0 0 -0 0</pose>
        <mass>3.7948</mass>
        <inertia>
          <ixx>8.4592e-05</ixx>
          <ixy>0</ixy>
          <ixz>0</ixz>
          <iyy>8.4592e-05</iyy>
          <iyz>0</iyz>
          <izz>4.9222e-05</izz>
        </inertia>
      </inertial>
      <collision name='left_roller_ne_link_collision'>
        <pose>0 0 0 0 -0 0</pose>
        <geometry>
          <mesh>
            <scale>1 1 1</scale>
            <uri>/home/jgy/RMUC_simulation/src/sentry_simulation/mesh/omni/roller.stl</uri>
          </mesh>
        </geometry>
        <surface>
          <contact>
            <ode/>
          </contact>
          <friction>
            <ode/>
            <torsional>
              <ode/>
            </torsional>
          </friction>
          <bounce/>
        </surface>
        <max_contacts>10</max_contacts>
      </collision>
      <visual name='left_roller_ne_link_visual'>
        <pose>0 0 0 0 -0 0</pose>
        <geometry>
          <mesh>
            <scale>1 1 1</scale>
            <uri>/home/jgy/RMUC_simulation/src/sentry_simulation/mesh/omni/roller.stl</uri>
          </mesh>
        </geometry>
        <material>
          <script>
            <name>Gazebo/Black</name>
            <uri>file://media/materials/scripts/gazebo.material</uri>
          </script>
        </material>
      </visual>
      <pose>0 0 0 0 -0 0</pose>
      <self_collide>0</self_collide>
      <enable_wind>0</enable_wind>
      <kinematic>0</kinematic>
    </link>
    <joint name='left_roller_nw_joint' type='revolute'>
      <pose relative_to='left_wheel_link'>-0.009581 0.009581 -0.0055 -1.5708 -0 2.35619</pose>
      <parent>left_wheel_link</parent>
      <child>left_roller_nw_link</child>
      <axis>
        <xyz>0 0 1</xyz>
        <limit>
          <lower>-1e+16</lower>
          <upper>1e+16</upper>
        </limit>
        <dynamics>
          <spring_reference>0</spring_reference>
          <spring_stiffness>0</spring_stiffness>
        </dynamics>
      </axis>
    </joint>
    <link name='left_roller_nw_link'>
      <pose relative_to='left_roller_nw_joint'>0 0 0 0 -0 0</pose>
      <inertial>
        <pose>0 0 0 0 -0 0</pose>
        <mass>3.7948</mass>
        <inertia>
          <ixx>8.4592e-05</ixx>
          <ixy>0</ixy>
          <ixz>0</ixz>
          <iyy>8.4592e-05</iyy>
          <iyz>0</iyz>
          <izz>4.9222e-05</izz>
        </inertia>
      </inertial>
      <collision name='left_roller_nw_link_collision'>
        <pose>0 0 0 0 -0 0</pose>
        <geometry>
          <mesh>
            <scale>1 1 1</scale>
            <uri>/home/jgy/RMUC_simulation/src/sentry_simulation/mesh/omni/roller.stl</uri>
          </mesh>
        </geometry>
        <surface>
          <contact>
            <ode/>
          </contact>
          <friction>
            <ode/>
            <torsional>
              <ode/>
            </torsional>
          </friction>
          <bounce/>
        </surface>
        <max_contacts>10</max_contacts>
      </collision>
      <visual name='left_roller_nw_link_visual'>
        <pose>0 0 0 0 -0 0</pose>
        <geometry>
          <mesh>
            <scale>1 1 1</scale>
            <uri>/home/jgy/RMUC_simulation/src/sentry_simulation/mesh/omni/roller.stl</uri>
          </mesh>
        </geometry>
        <material>
          <script>
            <name>Gazebo/Black</name>
            <uri>file://media/materials/scripts/gazebo.material</uri>
          </script>
        </material>
      </visual>
      <pose>0 0 0 0 -0 0</pose>
      <self_collide>0</self_collide>
      <enable_wind>0</enable_wind>
      <kinematic>0</kinematic>
    </link>
    <joint name='left_roller_s_joint' type='revolute'>
      <pose relative_to='left_wheel_link'>0 -0.01355 0.0055 -1.5708 -0 -1.5708</pose>
      <parent>left_wheel_link</parent>
      <child>left_roller_s_link</child>
      <axis>
        <xyz>0 0 1</xyz>
        <limit>
          <lower>-1e+16</lower>
          <upper>1e+16</upper>
        </limit>
        <dynamics>
          <spring_reference>0</spring_reference>
          <spring_stiffness>0</spring_stiffness>
        </dynamics>
      </axis>
    </joint>
    <link name='left_roller_s_link'>
      <pose relative_to='left_roller_s_joint'>0 0 0 0 -0 0</pose>
      <inertial>
        <pose>0 0 0 0 -0 0</pose>
        <mass>3.7948</mass>
        <inertia>
          <ixx>8.4592e-05</ixx>
          <ixy>0</ixy>
          <ixz>0</ixz>
          <iyy>8.4592e-05</iyy>
          <iyz>0</iyz>
          <izz>4.9222e-05</izz>
        </inertia>
      </inertial>
      <collision name='left_roller_s_link_collision'>
        <pose>0 0 0 0 -0 0</pose>
        <geometry>
          <mesh>
            <scale>1 1 1</scale>
            <uri>/home/jgy/RMUC_simulation/src/sentry_simulation/mesh/omni/roller.stl</uri>
          </mesh>
        </geometry>
        <surface>
          <contact>
            <ode/>
          </contact>
          <friction>
            <ode/>
            <torsional>
              <ode/>
            </torsional>
          </friction>
          <bounce/>
        </surface>
        <max_contacts>10</max_contacts>
      </collision>
      <visual name='left_roller_s_link_visual'>
        <pose>0 0 0 0 -0 0</pose>
        <geometry>
          <mesh>
            <scale>1 1 1</scale>
            <uri>/home/jgy/RMUC_simulation/src/sentry_simulation/mesh/omni/roller.stl</uri>
          </mesh>
        </geometry>
        <material>
          <script>
            <name>Gazebo/Black</name>
            <uri>file://media/materials/scripts/gazebo.material</uri>
          </script>
        </material>
      </visual>
      <pose>0 0 0 0 -0 0</pose>
      <self_collide>0</self_collide>
      <enable_wind>0</enable_wind>
      <kinematic>0</kinematic>
    </link>
    <joint name='left_roller_se_joint' type='revolute'>
      <pose relative_to='left_wheel_link'>0.009581 -0.009581 -0.0055 -1.5708 0 -0.785398</pose>
      <parent>left_wheel_link</parent>
      <child>left_roller_se_link</child>
      <axis>
        <xyz>0 0 1</xyz>
        <limit>
          <lower>-1e+16</lower>
          <upper>1e+16</upper>
        </limit>
        <dynamics>
          <spring_reference>0</spring_reference>
          <spring_stiffness>0</spring_stiffness>
        </dynamics>
      </axis>
    </joint>
    <link name='left_roller_se_link'>
      <pose relative_to='left_roller_se_joint'>0 0 0 0 -0 0</pose>
      <inertial>
        <pose>0 0 0 0 -0 0</pose>
        <mass>3.7948</mass>
        <inertia>
          <ixx>8.4592e-05</ixx>
          <ixy>0</ixy>
          <ixz>0</ixz>
          <iyy>8.4592e-05</iyy>
          <iyz>0</iyz>
          <izz>4.9222e-05</izz>
        </inertia>
      </inertial>
      <collision name='left_roller_se_link_collision'>
        <pose>0 0 0 0 -0 0</pose>
        <geometry>
          <mesh>
            <scale>1 1 1</scale>
            <uri>/home/jgy/RMUC_simulation/src/sentry_simulation/mesh/omni/roller.stl</uri>
          </mesh>
        </geometry>
        <surface>
          <contact>
            <ode/>
          </contact>
          <friction>
            <ode/>
            <torsional>
              <ode/>
            </torsional>
          </friction>
          <bounce/>
        </surface>
        <max_contacts>10</max_contacts>
      </collision>
      <visual name='left_roller_se_link_visual'>
        <pose>0 0 0 0 -0 0</pose>
        <geometry>
          <mesh>
            <scale>1 1 1</scale>
            <uri>/home/jgy/RMUC_simulation/src/sentry_simulation/mesh/omni/roller.stl</uri>
          </mesh>
        </geometry>
        <material>
          <script>
            <name>Gazebo/Black</name>
            <uri>file://media/materials/scripts/gazebo.material</uri>
          </script>
        </material>
      </visual>
      <pose>0 0 0 0 -0 0</pose>
      <self_collide>0</self_collide>
      <enable_wind>0</enable_wind>
      <kinematic>0</kinematic>
    </link>
    <joint name='left_roller_sw_joint' type='revolute'>
      <pose relative_to='left_wheel_link'>-0.009581 -0.009581 -0.0055 -1.5708 -0 -2.35619</pose>
      <parent>left_wheel_link</parent>
      <child>left_roller_sw_link</child>
      <axis>
        <xyz>0 0 1</xyz>
        <limit>
          <lower>-1e+16</lower>
          <upper>1e+16</upper>
        </limit>
        <dynamics>
          <spring_reference>0</spring_reference>
          <spring_stiffness>0</spring_stiffness>
        </dynamics>
      </axis>
    </joint>
    <link name='left_roller_sw_link'>
      <pose relative_to='left_roller_sw_joint'>0 0 0 0 -0 0</pose>
      <inertial>
        <pose>0 0 0 0 -0 0</pose>
        <mass>3.7948</mass>
        <inertia>
          <ixx>8.4592e-05</ixx>
          <ixy>0</ixy>
          <ixz>0</ixz>
          <iyy>8.4592e-05</iyy>
          <iyz>0</iyz>
          <izz>4.9222e-05</izz>
        </inertia>
      </inertial>
      <collision name='left_roller_sw_link_collision'>
        <pose>0 0 0 0 -0 0</pose>
        <geometry>
          <mesh>
            <scale>1 1 1</scale>
            <uri>/home/jgy/RMUC_simulation/src/sentry_simulation/mesh/omni/roller.stl</uri>
          </mesh>
        </geometry>
        <surface>
          <contact>
            <ode/>
          </contact>
          <friction>
            <ode/>
            <torsional>
              <ode/>
            </torsional>
          </friction>
          <bounce/>
        </surface>
        <max_contacts>10</max_contacts>
      </collision>
      <visual name='left_roller_sw_link_visual'>
        <pose>0 0 0 0 -0 0</pose>
        <geometry>
          <mesh>
            <scale>1 1 1</scale>
            <uri>/home/jgy/RMUC_simulation/src/sentry_simulation/mesh/omni/roller.stl</uri>
          </mesh>
        </geometry>
        <material>
          <script>
            <name>Gazebo/Black</name>
            <uri>file://media/materials/scripts/gazebo.material</uri>
          </script>
        </material>
      </visual>
      <pose>0 0 0 0 -0 0</pose>
      <self_collide>0</self_collide>
      <enable_wind>0</enable_wind>
      <kinematic>0</kinematic>
    </link>
    <joint name='left_roller_w_joint' type='revolute'>
      <pose relative_to='left_wheel_link'>-0.01355 0 0.0055 -1.5708 -0 3.14159</pose>
      <parent>left_wheel_link</parent>
      <child>left_roller_w_link</child>
      <axis>
        <xyz>0 0 1</xyz>
        <limit>
          <lower>-1e+16</lower>
          <upper>1e+16</upper>
        </limit>
        <dynamics>
          <spring_reference>0</spring_reference>
          <spring_stiffness>0</spring_stiffness>
        </dynamics>
      </axis>
    </joint>
    <link name='left_roller_w_link'>
      <pose relative_to='left_roller_w_joint'>0 0 0 0 -0 0</pose>
      <inertial>
        <pose>0 0 0 0 -0 0</pose>
        <mass>3.7948</mass>
        <inertia>
          <ixx>8.4592e-05</ixx>
          <ixy>0</ixy>
          <ixz>0</ixz>
          <iyy>8.4592e-05</iyy>
          <iyz>0</iyz>
          <izz>4.9222e-05</izz>
        </inertia>
      </inertial>
      <collision name='left_roller_w_link_collision'>
        <pose>0 0 0 0 -0 0</pose>
        <geometry>
          <mesh>
            <scale>1 1 1</scale>
            <uri>/home/jgy/RMUC_simulation/src/sentry_simulation/mesh/omni/roller.stl</uri>
          </mesh>
        </geometry>
        <surface>
          <contact>
            <ode/>
          </contact>
          <friction>
            <ode/>
            <torsional>
              <ode/>
            </torsional>
          </friction>
          <bounce/>
        </surface>
        <max_contacts>10</max_contacts>
      </collision>
      <visual name='left_roller_w_link_visual'>
        <pose>0 0 0 0 -0 0</pose>
        <geometry>
          <mesh>
            <scale>1 1 1</scale>
            <uri>/home/jgy/RMUC_simulation/src/sentry_simulation/mesh/omni/roller.stl</uri>
          </mesh>
        </geometry>
        <material>
          <script>
            <name>Gazebo/Black</name>
            <uri>file://media/materials/scripts/gazebo.material</uri>
          </script>
        </material>
      </visual>
      <pose>0 0 0 0 -0 0</pose>
      <self_collide>0</self_collide>
      <enable_wind>0</enable_wind>
      <kinematic>0</kinematic>
    </link>
    <joint name='rear_wheel_joint' type='revolute'>
      <pose relative_to='base_link'>0 -0.04 0 1.5708 -0 3.14159</pose>
      <parent>base_link</parent>
      <child>rear_wheel_link</child>
      <axis>
        <xyz>0 0 1</xyz>
        <limit>
          <lower>-1e+16</lower>
          <upper>1e+16</upper>
        </limit>
        <dynamics>
          <spring_reference>0</spring_reference>
          <spring_stiffness>0</spring_stiffness>
        </dynamics>
      </axis>
    </joint>
    <link name='rear_wheel_link'>
      <pose relative_to='rear_wheel_joint'>0 0 0 0 -0 0</pose>
      <inertial>
        <pose>0 0 -0.000343 0 -0 0</pose>
        <mass>41.7879</mass>
        <inertia>
          <ixx>0.00331842</ixx>
          <ixy>0</ixy>
          <ixz>0</ixz>
          <iyy>0.00331842</iyy>
          <iyz>0</iyz>
          <izz>0.00470166</izz>
        </inertia>
      </inertial>
      <collision name='rear_wheel_link_collision'>
        <pose>0 0 0 0 -0 0</pose>
        <geometry>
          <mesh>
            <scale>1 1 1</scale>
            <uri>/home/jgy/RMUC_simulation/src/sentry_simulation/mesh/omni/wheel.stl</uri>
          </mesh>
        </geometry>
        <surface>
          <contact>
            <ode/>
          </contact>
          <friction>
            <ode/>
            <torsional>
              <ode/>
            </torsional>
          </friction>
          <bounce/>
        </surface>
        <max_contacts>10</max_contacts>
      </collision>
      <visual name='rear_wheel_link_visual'>
        <pose>0 0 0 0 -0 0</pose>
        <geometry>
          <mesh>
            <scale>1 1 1</scale>
            <uri>/home/jgy/RMUC_simulation/src/sentry_simulation/mesh/omni/wheel.stl</uri>
          </mesh>
        </geometry>
        <material>
          <script>
            <name>Gazebo/Green</name>
            <uri>file://media/materials/scripts/gazebo.material</uri>
          </script>
        </material>
      </visual>
      <pose>0 0 0 0 -0 0</pose>
      <self_collide>0</self_collide>
      <enable_wind>0</enable_wind>
      <kinematic>0</kinematic>
    </link>
    <joint name='rear_roller_e_joint' type='revolute'>
      <pose relative_to='rear_wheel_link'>0.01355 0 0.0055 -1.5708 0 0</pose>
      <parent>rear_wheel_link</parent>
      <child>rear_roller_e_link</child>
      <axis>
        <xyz>0 0 1</xyz>
        <limit>
          <lower>-1e+16</lower>
          <upper>1e+16</upper>
        </limit>
        <dynamics>
          <spring_reference>0</spring_reference>
          <spring_stiffness>0</spring_stiffness>
        </dynamics>
      </axis>
    </joint>
    <link name='rear_roller_e_link'>
      <pose relative_to='rear_roller_e_joint'>0 0 0 0 -0 0</pose>
      <inertial>
        <pose>0 0 0 0 -0 0</pose>
        <mass>3.7948</mass>
        <inertia>
          <ixx>8.4592e-05</ixx>
          <ixy>0</ixy>
          <ixz>0</ixz>
          <iyy>8.4592e-05</iyy>
          <iyz>0</iyz>
          <izz>4.9222e-05</izz>
        </inertia>
      </inertial>
      <collision name='rear_roller_e_link_collision'>
        <pose>0 0 0 0 -0 0</pose>
        <geometry>
          <mesh>
            <scale>1 1 1</scale>
            <uri>/home/jgy/RMUC_simulation/src/sentry_simulation/mesh/omni/roller.stl</uri>
          </mesh>
        </geometry>
        <surface>
          <contact>
            <ode/>
          </contact>
          <friction>
            <ode/>
            <torsional>
              <ode/>
            </torsional>
          </friction>
          <bounce/>
        </surface>
        <max_contacts>10</max_contacts>
      </collision>
      <visual name='rear_roller_e_link_visual'>
        <pose>0 0 0 0 -0 0</pose>
        <geometry>
          <mesh>
            <scale>1 1 1</scale>
            <uri>/home/jgy/RMUC_simulation/src/sentry_simulation/mesh/omni/roller.stl</uri>
          </mesh>
        </geometry>
        <material>
          <script>
            <name>Gazebo/Black</name>
            <uri>file://media/materials/scripts/gazebo.material</uri>
          </script>
        </material>
      </visual>
      <pose>0 0 0 0 -0 0</pose>
      <self_collide>0</self_collide>
      <enable_wind>0</enable_wind>
      <kinematic>0</kinematic>
    </link>
    <joint name='rear_roller_n_joint' type='revolute'>
      <pose relative_to='rear_wheel_link'>0 0.01355 0.0055 -1.5708 0 1.5708</pose>
      <parent>rear_wheel_link</parent>
      <child>rear_roller_n_link</child>
      <axis>
        <xyz>0 0 1</xyz>
        <limit>
          <lower>-1e+16</lower>
          <upper>1e+16</upper>
        </limit>
        <dynamics>
          <spring_reference>0</spring_reference>
          <spring_stiffness>0</spring_stiffness>
        </dynamics>
      </axis>
    </joint>
    <link name='rear_roller_n_link'>
      <pose relative_to='rear_roller_n_joint'>0 0 0 0 -0 0</pose>
      <inertial>
        <pose>0 0 0 0 -0 0</pose>
        <mass>3.7948</mass>
        <inertia>
          <ixx>8.4592e-05</ixx>
          <ixy>0</ixy>
          <ixz>0</ixz>
          <iyy>8.4592e-05</iyy>
          <iyz>0</iyz>
          <izz>4.9222e-05</izz>
        </inertia>
      </inertial>
      <collision name='rear_roller_n_link_collision'>
        <pose>0 0 0 0 -0 0</pose>
        <geometry>
          <mesh>
            <scale>1 1 1</scale>
            <uri>/home/jgy/RMUC_simulation/src/sentry_simulation/mesh/omni/roller.stl</uri>
          </mesh>
        </geometry>
        <surface>
          <contact>
            <ode/>
          </contact>
          <friction>
            <ode/>
            <torsional>
              <ode/>
            </torsional>
          </friction>
          <bounce/>
        </surface>
        <max_contacts>10</max_contacts>
      </collision>
      <visual name='rear_roller_n_link_visual'>
        <pose>0 0 0 0 -0 0</pose>
        <geometry>
          <mesh>
            <scale>1 1 1</scale>
            <uri>/home/jgy/RMUC_simulation/src/sentry_simulation/mesh/omni/roller.stl</uri>
          </mesh>
        </geometry>
        <material>
          <script>
            <name>Gazebo/Black</name>
            <uri>file://media/materials/scripts/gazebo.material</uri>
          </script>
        </material>
      </visual>
      <pose>0 0 0 0 -0 0</pose>
      <self_collide>0</self_collide>
      <enable_wind>0</enable_wind>
      <kinematic>0</kinematic>
    </link>
    <joint name='rear_roller_ne_joint' type='revolute'>
      <pose relative_to='rear_wheel_link'>0.009581 0.009581 -0.0055 -1.5708 -0 0.785398</pose>
      <parent>rear_wheel_link</parent>
      <child>rear_roller_ne_link</child>
      <axis>
        <xyz>0 0 1</xyz>
        <limit>
          <lower>-1e+16</lower>
          <upper>1e+16</upper>
        </limit>
        <dynamics>
          <spring_reference>0</spring_reference>
          <spring_stiffness>0</spring_stiffness>
        </dynamics>
      </axis>
    </joint>
    <link name='rear_roller_ne_link'>
      <pose relative_to='rear_roller_ne_joint'>0 0 0 0 -0 0</pose>
      <inertial>
        <pose>0 0 0 0 -0 0</pose>
        <mass>3.7948</mass>
        <inertia>
          <ixx>8.4592e-05</ixx>
          <ixy>0</ixy>
          <ixz>0</ixz>
          <iyy>8.4592e-05</iyy>
          <iyz>0</iyz>
          <izz>4.9222e-05</izz>
        </inertia>
      </inertial>
      <collision name='rear_roller_ne_link_collision'>
        <pose>0 0 0 0 -0 0</pose>
        <geometry>
          <mesh>
            <scale>1 1 1</scale>
            <uri>/home/jgy/RMUC_simulation/src/sentry_simulation/mesh/omni/roller.stl</uri>
          </mesh>
        </geometry>
        <surface>
          <contact>
            <ode/>
          </contact>
          <friction>
            <ode/>
            <torsional>
              <ode/>
            </torsional>
          </friction>
          <bounce/>
        </surface>
        <max_contacts>10</max_contacts>
      </collision>
      <visual name='rear_roller_ne_link_visual'>
        <pose>0 0 0 0 -0 0</pose>
        <geometry>
          <mesh>
            <scale>1 1 1</scale>
            <uri>/home/jgy/RMUC_simulation/src/sentry_simulation/mesh/omni/roller.stl</uri>
          </mesh>
        </geometry>
        <material>
          <script>
            <name>Gazebo/Black</name>
            <uri>file://media/materials/scripts/gazebo.material</uri>
          </script>
        </material>
      </visual>
      <pose>0 0 0 0 -0 0</pose>
      <self_collide>0</self_collide>
      <enable_wind>0</enable_wind>
      <kinematic>0</kinematic>
    </link>
    <joint name='rear_roller_nw_joint' type='revolute'>
      <pose relative_to='rear_wheel_link'>-0.009581 0.009581 -0.0055 -1.5708 -0 2.35619</pose>
      <parent>rear_wheel_link</parent>
      <child>rear_roller_nw_link</child>
      <axis>
        <xyz>0 0 1</xyz>
        <limit>
          <lower>-1e+16</lower>
          <upper>1e+16</upper>
        </limit>
        <dynamics>
          <spring_reference>0</spring_reference>
          <spring_stiffness>0</spring_stiffness>
        </dynamics>
      </axis>
    </joint>
    <link name='rear_roller_nw_link'>
      <pose relative_to='rear_roller_nw_joint'>0 0 0 0 -0 0</pose>
      <inertial>
        <pose>0 0 0 0 -0 0</pose>
        <mass>3.7948</mass>
        <inertia>
          <ixx>8.4592e-05</ixx>
          <ixy>0</ixy>
          <ixz>0</ixz>
          <iyy>8.4592e-05</iyy>
          <iyz>0</iyz>
          <izz>4.9222e-05</izz>
        </inertia>
      </inertial>
      <collision name='rear_roller_nw_link_collision'>
        <pose>0 0 0 0 -0 0</pose>
        <geometry>
          <mesh>
            <scale>1 1 1</scale>
            <uri>/home/jgy/RMUC_simulation/src/sentry_simulation/mesh/omni/roller.stl</uri>
          </mesh>
        </geometry>
        <surface>
          <contact>
            <ode/>
          </contact>
          <friction>
            <ode/>
            <torsional>
              <ode/>
            </torsional>
          </friction>
          <bounce/>
        </surface>
        <max_contacts>10</max_contacts>
      </collision>
      <visual name='rear_roller_nw_link_visual'>
        <pose>0 0 0 0 -0 0</pose>
        <geometry>
          <mesh>
            <scale>1 1 1</scale>
            <uri>/home/jgy/RMUC_simulation/src/sentry_simulation/mesh/omni/roller.stl</uri>
          </mesh>
        </geometry>
        <material>
          <script>
            <name>Gazebo/Black</name>
            <uri>file://media/materials/scripts/gazebo.material</uri>
          </script>
        </material>
      </visual>
      <pose>0 0 0 0 -0 0</pose>
      <self_collide>0</self_collide>
      <enable_wind>0</enable_wind>
      <kinematic>0</kinematic>
    </link>
    <joint name='rear_roller_s_joint' type='revolute'>
      <pose relative_to='rear_wheel_link'>0 -0.01355 0.0055 -1.5708 -0 -1.5708</pose>
      <parent>rear_wheel_link</parent>
      <child>rear_roller_s_link</child>
      <axis>
        <xyz>0 0 1</xyz>
        <limit>
          <lower>-1e+16</lower>
          <upper>1e+16</upper>
        </limit>
        <dynamics>
          <spring_reference>0</spring_reference>
          <spring_stiffness>0</spring_stiffness>
        </dynamics>
      </axis>
    </joint>
    <link name='rear_roller_s_link'>
      <pose relative_to='rear_roller_s_joint'>0 0 0 0 -0 0</pose>
      <inertial>
        <pose>0 0 0 0 -0 0</pose>
        <mass>3.7948</mass>
        <inertia>
          <ixx>8.4592e-05</ixx>
          <ixy>0</ixy>
          <ixz>0</ixz>
          <iyy>8.4592e-05</iyy>
          <iyz>0</iyz>
          <izz>4.9222e-05</izz>
        </inertia>
      </inertial>
      <collision name='rear_roller_s_link_collision'>
        <pose>0 0 0 0 -0 0</pose>
        <geometry>
          <mesh>
            <scale>1 1 1</scale>
            <uri>/home/jgy/RMUC_simulation/src/sentry_simulation/mesh/omni/roller.stl</uri>
          </mesh>
        </geometry>
        <surface>
          <contact>
            <ode/>
          </contact>
          <friction>
            <ode/>
            <torsional>
              <ode/>
            </torsional>
          </friction>
          <bounce/>
        </surface>
        <max_contacts>10</max_contacts>
      </collision>
      <visual name='rear_roller_s_link_visual'>
        <pose>0 0 0 0 -0 0</pose>
        <geometry>
          <mesh>
            <scale>1 1 1</scale>
            <uri>/home/jgy/RMUC_simulation/src/sentry_simulation/mesh/omni/roller.stl</uri>
          </mesh>
        </geometry>
        <material>
          <script>
            <name>Gazebo/Black</name>
            <uri>file://media/materials/scripts/gazebo.material</uri>
          </script>
        </material>
      </visual>
      <pose>0 0 0 0 -0 0</pose>
      <self_collide>0</self_collide>
      <enable_wind>0</enable_wind>
      <kinematic>0</kinematic>
    </link>
    <joint name='rear_roller_se_joint' type='revolute'>
      <pose relative_to='rear_wheel_link'>0.009581 -0.009581 -0.0055 -1.5708 0 -0.785398</pose>
      <parent>rear_wheel_link</parent>
      <child>rear_roller_se_link</child>
      <axis>
        <xyz>0 0 1</xyz>
        <limit>
          <lower>-1e+16</lower>
          <upper>1e+16</upper>
        </limit>
        <dynamics>
          <spring_reference>0</spring_reference>
          <spring_stiffness>0</spring_stiffness>
        </dynamics>
      </axis>
    </joint>
    <link name='rear_roller_se_link'>
      <pose relative_to='rear_roller_se_joint'>0 0 0 0 -0 0</pose>
      <inertial>
        <pose>0 0 0 0 -0 0</pose>
        <mass>3.7948</mass>
        <inertia>
          <ixx>8.4592e-05</ixx>
          <ixy>0</ixy>
          <ixz>0</ixz>
          <iyy>8.4592e-05</iyy>
          <iyz>0</iyz>
          <izz>4.9222e-05</izz>
        </inertia>
      </inertial>
      <collision name='rear_roller_se_link_collision'>
        <pose>0 0 0 0 -0 0</pose>
        <geometry>
          <mesh>
            <scale>1 1 1</scale>
            <uri>/home/jgy/RMUC_simulation/src/sentry_simulation/mesh/omni/roller.stl</uri>
          </mesh>
        </geometry>
        <surface>
          <contact>
            <ode/>
          </contact>
          <friction>
            <ode/>
            <torsional>
              <ode/>
            </torsional>
          </friction>
          <bounce/>
        </surface>
        <max_contacts>10</max_contacts>
      </collision>
      <visual name='rear_roller_se_link_visual'>
        <pose>0 0 0 0 -0 0</pose>
        <geometry>
          <mesh>
            <scale>1 1 1</scale>
            <uri>/home/jgy/RMUC_simulation/src/sentry_simulation/mesh/omni/roller.stl</uri>
          </mesh>
        </geometry>
        <material>
          <script>
            <name>Gazebo/Black</name>
            <uri>file://media/materials/scripts/gazebo.material</uri>
          </script>
        </material>
      </visual>
      <pose>0 0 0 0 -0 0</pose>
      <self_collide>0</self_collide>
      <enable_wind>0</enable_wind>
      <kinematic>0</kinematic>
    </link>
    <joint name='rear_roller_sw_joint' type='revolute'>
      <pose relative_to='rear_wheel_link'>-0.009581 -0.009581 -0.0055 -1.5708 -0 -2.35619</pose>
      <parent>rear_wheel_link</parent>
      <child>rear_roller_sw_link</child>
      <axis>
        <xyz>0 0 1</xyz>
        <limit>
          <lower>-1e+16</lower>
          <upper>1e+16</upper>
        </limit>
        <dynamics>
          <spring_reference>0</spring_reference>
          <spring_stiffness>0</spring_stiffness>
        </dynamics>
      </axis>
    </joint>
    <link name='rear_roller_sw_link'>
      <pose relative_to='rear_roller_sw_joint'>0 0 0 0 -0 0</pose>
      <inertial>
        <pose>0 0 0 0 -0 0</pose>
        <mass>3.7948</mass>
        <inertia>
          <ixx>8.4592e-05</ixx>
          <ixy>0</ixy>
          <ixz>0</ixz>
          <iyy>8.4592e-05</iyy>
          <iyz>0</iyz>
          <izz>4.9222e-05</izz>
        </inertia>
      </inertial>
      <collision name='rear_roller_sw_link_collision'>
        <pose>0 0 0 0 -0 0</pose>
        <geometry>
          <mesh>
            <scale>1 1 1</scale>
            <uri>/home/jgy/RMUC_simulation/src/sentry_simulation/mesh/omni/roller.stl</uri>
          </mesh>
        </geometry>
        <surface>
          <contact>
            <ode/>
          </contact>
          <friction>
            <ode/>
            <torsional>
              <ode/>
            </torsional>
          </friction>
          <bounce/>
        </surface>
        <max_contacts>10</max_contacts>
      </collision>
      <visual name='rear_roller_sw_link_visual'>
        <pose>0 0 0 0 -0 0</pose>
        <geometry>
          <mesh>
            <scale>1 1 1</scale>
            <uri>/home/jgy/RMUC_simulation/src/sentry_simulation/mesh/omni/roller.stl</uri>
          </mesh>
        </geometry>
        <material>
          <script>
            <name>Gazebo/Black</name>
            <uri>file://media/materials/scripts/gazebo.material</uri>
          </script>
        </material>
      </visual>
      <pose>0 0 0 0 -0 0</pose>
      <self_collide>0</self_collide>
      <enable_wind>0</enable_wind>
      <kinematic>0</kinematic>
    </link>
    <joint name='rear_roller_w_joint' type='revolute'>
      <pose relative_to='rear_wheel_link'>-0.01355 0 0.0055 -1.5708 -0 3.14159</pose>
      <parent>rear_wheel_link</parent>
      <child>rear_roller_w_link</child>
      <axis>
        <xyz>0 0 1</xyz>
        <limit>
          <lower>-1e+16</lower>
          <upper>1e+16</upper>
        </limit>
        <dynamics>
          <spring_reference>0</spring_reference>
          <spring_stiffness>0</spring_stiffness>
        </dynamics>
      </axis>
    </joint>
    <link name='rear_roller_w_link'>
      <pose relative_to='rear_roller_w_joint'>0 0 0 0 -0 0</pose>
      <inertial>
        <pose>0 0 0 0 -0 0</pose>
        <mass>3.7948</mass>
        <inertia>
          <ixx>8.4592e-05</ixx>
          <ixy>0</ixy>
          <ixz>0</ixz>
          <iyy>8.4592e-05</iyy>
          <iyz>0</iyz>
          <izz>4.9222e-05</izz>
        </inertia>
      </inertial>
      <collision name='rear_roller_w_link_collision'>
        <pose>0 0 0 0 -0 0</pose>
        <geometry>
          <mesh>
            <scale>1 1 1</scale>
            <uri>/home/jgy/RMUC_simulation/src/sentry_simulation/mesh/omni/roller.stl</uri>
          </mesh>
        </geometry>
        <surface>
          <contact>
            <ode/>
          </contact>
          <friction>
            <ode/>
            <torsional>
              <ode/>
            </torsional>
          </friction>
          <bounce/>
        </surface>
        <max_contacts>10</max_contacts>
      </collision>
      <visual name='rear_roller_w_link_visual'>
        <pose>0 0 0 0 -0 0</pose>
        <geometry>
          <mesh>
            <scale>1 1 1</scale>
            <uri>/home/jgy/RMUC_simulation/src/sentry_simulation/mesh/omni/roller.stl</uri>
          </mesh>
        </geometry>
        <material>
          <script>
            <name>Gazebo/Black</name>
            <uri>file://media/materials/scripts/gazebo.material</uri>
          </script>
        </material>
      </visual>
      <pose>0 0 0 0 -0 0</pose>
      <self_collide>0</self_collide>
      <enable_wind>0</enable_wind>
      <kinematic>0</kinematic>
    </link>
    <joint name='right_wheel_joint' type='revolute'>
      <pose relative_to='base_link'>0.034641 0.02 0 1.5708 -0 -1.0472</pose>
      <parent>base_link</parent>
      <child>right_wheel_link</child>
      <axis>
        <xyz>0 0 1</xyz>
        <limit>
          <lower>-1e+16</lower>
          <upper>1e+16</upper>
        </limit>
        <dynamics>
          <spring_reference>0</spring_reference>
          <spring_stiffness>0</spring_stiffness>
        </dynamics>
      </axis>
    </joint>
    <link name='right_wheel_link'>
      <pose relative_to='right_wheel_joint'>0 0 0 0 -0 0</pose>
      <inertial>
        <pose>0 0 -0.000343 0 -0 0</pose>
        <mass>41.7879</mass>
        <inertia>
          <ixx>0.00331842</ixx>
          <ixy>0</ixy>
          <ixz>0</ixz>
          <iyy>0.00331842</iyy>
          <iyz>0</iyz>
          <izz>0.00470166</izz>
        </inertia>
      </inertial>
      <collision name='right_wheel_link_collision'>
        <pose>0 0 0 0 -0 0</pose>
        <geometry>
          <mesh>
            <scale>1 1 1</scale>
            <uri>/home/jgy/RMUC_simulation/src/sentry_simulation/mesh/omni/wheel.stl</uri>
          </mesh>
        </geometry>
        <surface>
          <contact>
            <ode/>
          </contact>
          <friction>
            <ode/>
            <torsional>
              <ode/>
            </torsional>
          </friction>
          <bounce/>
        </surface>
        <max_contacts>10</max_contacts>
      </collision>
      <visual name='right_wheel_link_visual'>
        <pose>0 0 0 0 -0 0</pose>
        <geometry>
          <mesh>
            <scale>1 1 1</scale>
            <uri>/home/jgy/RMUC_simulation/src/sentry_simulation/mesh/omni/wheel.stl</uri>
          </mesh>
        </geometry>
        <material>
          <script>
            <name>Gazebo/Blue</name>
            <uri>file://media/materials/scripts/gazebo.material</uri>
          </script>
        </material>
      </visual>
      <pose>0 0 0 0 -0 0</pose>
      <self_collide>0</self_collide>
      <enable_wind>0</enable_wind>
      <kinematic>0</kinematic>
    </link>
    <joint name='right_roller_e_joint' type='revolute'>
      <pose relative_to='right_wheel_link'>0.01355 0 0.0055 -1.5708 0 0</pose>
      <parent>right_wheel_link</parent>
      <child>right_roller_e_link</child>
      <axis>
        <xyz>0 0 1</xyz>
        <limit>
          <lower>-1e+16</lower>
          <upper>1e+16</upper>
        </limit>
        <dynamics>
          <spring_reference>0</spring_reference>
          <spring_stiffness>0</spring_stiffness>
        </dynamics>
      </axis>
    </joint>
    <link name='right_roller_e_link'>
      <pose relative_to='right_roller_e_joint'>0 0 0 0 -0 0</pose>
      <inertial>
        <pose>0 0 0 0 -0 0</pose>
        <mass>3.7948</mass>
        <inertia>
          <ixx>8.4592e-05</ixx>
          <ixy>0</ixy>
          <ixz>0</ixz>
          <iyy>8.4592e-05</iyy>
          <iyz>0</iyz>
          <izz>4.9222e-05</izz>
        </inertia>
      </inertial>
      <collision name='right_roller_e_link_collision'>
        <pose>0 0 0 0 -0 0</pose>
        <geometry>
          <mesh>
            <scale>1 1 1</scale>
            <uri>/home/jgy/RMUC_simulation/src/sentry_simulation/mesh/omni/roller.stl</uri>
          </mesh>
        </geometry>
        <surface>
          <contact>
            <ode/>
          </contact>
          <friction>
            <ode/>
            <torsional>
              <ode/>
            </torsional>
          </friction>
          <bounce/>
        </surface>
        <max_contacts>10</max_contacts>
      </collision>
      <visual name='right_roller_e_link_visual'>
        <pose>0 0 0 0 -0 0</pose>
        <geometry>
          <mesh>
            <scale>1 1 1</scale>
            <uri>/home/jgy/RMUC_simulation/src/sentry_simulation/mesh/omni/roller.stl</uri>
          </mesh>
        </geometry>
        <material>
          <script>
            <name>Gazebo/Black</name>
            <uri>file://media/materials/scripts/gazebo.material</uri>
          </script>
        </material>
      </visual>
      <pose>0 0 0 0 -0 0</pose>
      <self_collide>0</self_collide>
      <enable_wind>0</enable_wind>
      <kinematic>0</kinematic>
    </link>
    <joint name='right_roller_n_joint' type='revolute'>
      <pose relative_to='right_wheel_link'>0 0.01355 0.0055 -1.5708 0 1.5708</pose>
      <parent>right_wheel_link</parent>
      <child>right_roller_n_link</child>
      <axis>
        <xyz>0 0 1</xyz>
        <limit>
          <lower>-1e+16</lower>
          <upper>1e+16</upper>
        </limit>
        <dynamics>
          <spring_reference>0</spring_reference>
          <spring_stiffness>0</spring_stiffness>
        </dynamics>
      </axis>
    </joint>
    <link name='right_roller_n_link'>
      <pose relative_to='right_roller_n_joint'>0 0 0 0 -0 0</pose>
      <inertial>
        <pose>0 0 0 0 -0 0</pose>
        <mass>3.7948</mass>
        <inertia>
          <ixx>8.4592e-05</ixx>
          <ixy>0</ixy>
          <ixz>0</ixz>
          <iyy>8.4592e-05</iyy>
          <iyz>0</iyz>
          <izz>4.9222e-05</izz>
        </inertia>
      </inertial>
      <collision name='right_roller_n_link_collision'>
        <pose>0 0 0 0 -0 0</pose>
        <geometry>
          <mesh>
            <scale>1 1 1</scale>
            <uri>/home/jgy/RMUC_simulation/src/sentry_simulation/mesh/omni/roller.stl</uri>
          </mesh>
        </geometry>
        <surface>
          <contact>
            <ode/>
          </contact>
          <friction>
            <ode/>
            <torsional>
              <ode/>
            </torsional>
          </friction>
          <bounce/>
        </surface>
        <max_contacts>10</max_contacts>
      </collision>
      <visual name='right_roller_n_link_visual'>
        <pose>0 0 0 0 -0 0</pose>
        <geometry>
          <mesh>
            <scale>1 1 1</scale>
            <uri>/home/jgy/RMUC_simulation/src/sentry_simulation/mesh/omni/roller.stl</uri>
          </mesh>
        </geometry>
        <material>
          <script>
            <name>Gazebo/Black</name>
            <uri>file://media/materials/scripts/gazebo.material</uri>
          </script>
        </material>
      </visual>
      <pose>0 0 0 0 -0 0</pose>
      <self_collide>0</self_collide>
      <enable_wind>0</enable_wind>
      <kinematic>0</kinematic>
    </link>
    <joint name='right_roller_ne_joint' type='revolute'>
      <pose relative_to='right_wheel_link'>0.009581 0.009581 -0.0055 -1.5708 -0 0.785398</pose>
      <parent>right_wheel_link</parent>
      <child>right_roller_ne_link</child>
      <axis>
        <xyz>0 0 1</xyz>
        <limit>
          <lower>-1e+16</lower>
          <upper>1e+16</upper>
        </limit>
        <dynamics>
          <spring_reference>0</spring_reference>
          <spring_stiffness>0</spring_stiffness>
        </dynamics>
      </axis>
    </joint>
    <link name='right_roller_ne_link'>
      <pose relative_to='right_roller_ne_joint'>0 0 0 0 -0 0</pose>
      <inertial>
        <pose>0 0 0 0 -0 0</pose>
        <mass>3.7948</mass>
        <inertia>
          <ixx>8.4592e-05</ixx>
          <ixy>0</ixy>
          <ixz>0</ixz>
          <iyy>8.4592e-05</iyy>
          <iyz>0</iyz>
          <izz>4.9222e-05</izz>
        </inertia>
      </inertial>
      <collision name='right_roller_ne_link_collision'>
        <pose>0 0 0 0 -0 0</pose>
        <geometry>
          <mesh>
            <scale>1 1 1</scale>
            <uri>/home/jgy/RMUC_simulation/src/sentry_simulation/mesh/omni/roller.stl</uri>
          </mesh>
        </geometry>
        <surface>
          <contact>
            <ode/>
          </contact>
          <friction>
            <ode/>
            <torsional>
              <ode/>
            </torsional>
          </friction>
          <bounce/>
        </surface>
        <max_contacts>10</max_contacts>
      </collision>
      <visual name='right_roller_ne_link_visual'>
        <pose>0 0 0 0 -0 0</pose>
        <geometry>
          <mesh>
            <scale>1 1 1</scale>
            <uri>/home/jgy/RMUC_simulation/src/sentry_simulation/mesh/omni/roller.stl</uri>
          </mesh>
        </geometry>
        <material>
          <script>
            <name>Gazebo/Black</name>
            <uri>file://media/materials/scripts/gazebo.material</uri>
          </script>
        </material>
      </visual>
      <pose>0 0 0 0 -0 0</pose>
      <self_collide>0</self_collide>
      <enable_wind>0</enable_wind>
      <kinematic>0</kinematic>
    </link>
    <joint name='right_roller_nw_joint' type='revolute'>
      <pose relative_to='right_wheel_link'>-0.009581 0.009581 -0.0055 -1.5708 -0 2.35619</pose>
      <parent>right_wheel_link</parent>
      <child>right_roller_nw_link</child>
      <axis>
        <xyz>0 0 1</xyz>
        <limit>
          <lower>-1e+16</lower>
          <upper>1e+16</upper>
        </limit>
        <dynamics>
          <spring_reference>0</spring_reference>
          <spring_stiffness>0</spring_stiffness>
        </dynamics>
      </axis>
    </joint>
    <link name='right_roller_nw_link'>
      <pose relative_to='right_roller_nw_joint'>0 0 0 0 -0 0</pose>
      <inertial>
        <pose>0 0 0 0 -0 0</pose>
        <mass>3.7948</mass>
        <inertia>
          <ixx>8.4592e-05</ixx>
          <ixy>0</ixy>
          <ixz>0</ixz>
          <iyy>8.4592e-05</iyy>
          <iyz>0</iyz>
          <izz>4.9222e-05</izz>
        </inertia>
      </inertial>
      <collision name='right_roller_nw_link_collision'>
        <pose>0 0 0 0 -0 0</pose>
        <geometry>
          <mesh>
            <scale>1 1 1</scale>
            <uri>/home/jgy/RMUC_simulation/src/sentry_simulation/mesh/omni/roller.stl</uri>
          </mesh>
        </geometry>
        <surface>
          <contact>
            <ode/>
          </contact>
          <friction>
            <ode/>
            <torsional>
              <ode/>
            </torsional>
          </friction>
          <bounce/>
        </surface>
        <max_contacts>10</max_contacts>
      </collision>
      <visual name='right_roller_nw_link_visual'>
        <pose>0 0 0 0 -0 0</pose>
        <geometry>
          <mesh>
            <scale>1 1 1</scale>
            <uri>/home/jgy/RMUC_simulation/src/sentry_simulation/mesh/omni/roller.stl</uri>
          </mesh>
        </geometry>
        <material>
          <script>
            <name>Gazebo/Black</name>
            <uri>file://media/materials/scripts/gazebo.material</uri>
          </script>
        </material>
      </visual>
      <pose>0 0 0 0 -0 0</pose>
      <self_collide>0</self_collide>
      <enable_wind>0</enable_wind>
      <kinematic>0</kinematic>
    </link>
    <joint name='right_roller_s_joint' type='revolute'>
      <pose relative_to='right_wheel_link'>0 -0.01355 0.0055 -1.5708 -0 -1.5708</pose>
      <parent>right_wheel_link</parent>
      <child>right_roller_s_link</child>
      <axis>
        <xyz>0 0 1</xyz>
        <limit>
          <lower>-1e+16</lower>
          <upper>1e+16</upper>
        </limit>
        <dynamics>
          <spring_reference>0</spring_reference>
          <spring_stiffness>0</spring_stiffness>
        </dynamics>
      </axis>
    </joint>
    <link name='right_roller_s_link'>
      <pose relative_to='right_roller_s_joint'>0 0 0 0 -0 0</pose>
      <inertial>
        <pose>0 0 0 0 -0 0</pose>
        <mass>3.7948</mass>
        <inertia>
          <ixx>8.4592e-05</ixx>
          <ixy>0</ixy>
          <ixz>0</ixz>
          <iyy>8.4592e-05</iyy>
          <iyz>0</iyz>
          <izz>4.9222e-05</izz>
        </inertia>
      </inertial>
      <collision name='right_roller_s_link_collision'>
        <pose>0 0 0 0 -0 0</pose>
        <geometry>
          <mesh>
            <scale>1 1 1</scale>
            <uri>/home/jgy/RMUC_simulation/src/sentry_simulation/mesh/omni/roller.stl</uri>
          </mesh>
        </geometry>
        <surface>
          <contact>
            <ode/>
          </contact>
          <friction>
            <ode/>
            <torsional>
              <ode/>
            </torsional>
          </friction>
          <bounce/>
        </surface>
        <max_contacts>10</max_contacts>
      </collision>
      <visual name='right_roller_s_link_visual'>
        <pose>0 0 0 0 -0 0</pose>
        <geometry>
          <mesh>
            <scale>1 1 1</scale>
            <uri>/home/jgy/RMUC_simulation/src/sentry_simulation/mesh/omni/roller.stl</uri>
          </mesh>
        </geometry>
        <material>
          <script>
            <name>Gazebo/Black</name>
            <uri>file://media/materials/scripts/gazebo.material</uri>
          </script>
        </material>
      </visual>
      <pose>0 0 0 0 -0 0</pose>
      <self_collide>0</self_collide>
      <enable_wind>0</enable_wind>
      <kinematic>0</kinematic>
    </link>
    <joint name='right_roller_se_joint' type='revolute'>
      <pose relative_to='right_wheel_link'>0.009581 -0.009581 -0.0055 -1.5708 0 -0.785398</pose>
      <parent>right_wheel_link</parent>
      <child>right_roller_se_link</child>
      <axis>
        <xyz>0 0 1</xyz>
        <limit>
          <lower>-1e+16</lower>
          <upper>1e+16</upper>
        </limit>
        <dynamics>
          <spring_reference>0</spring_reference>
          <spring_stiffness>0</spring_stiffness>
        </dynamics>
      </axis>
    </joint>
    <link name='right_roller_se_link'>
      <pose relative_to='right_roller_se_joint'>0 0 0 0 -0 0</pose>
      <inertial>
        <pose>0 0 0 0 -0 0</pose>
        <mass>3.7948</mass>
        <inertia>
          <ixx>8.4592e-05</ixx>
          <ixy>0</ixy>
          <ixz>0</ixz>
          <iyy>8.4592e-05</iyy>
          <iyz>0</iyz>
          <izz>4.9222e-05</izz>
        </inertia>
      </inertial>
      <collision name='right_roller_se_link_collision'>
        <pose>0 0 0 0 -0 0</pose>
        <geometry>
          <mesh>
            <scale>1 1 1</scale>
            <uri>/home/jgy/RMUC_simulation/src/sentry_simulation/mesh/omni/roller.stl</uri>
          </mesh>
        </geometry>
        <surface>
          <contact>
            <ode/>
          </contact>
          <friction>
            <ode/>
            <torsional>
              <ode/>
            </torsional>
          </friction>
          <bounce/>
        </surface>
        <max_contacts>10</max_contacts>
      </collision>
      <visual name='right_roller_se_link_visual'>
        <pose>0 0 0 0 -0 0</pose>
        <geometry>
          <mesh>
            <scale>1 1 1</scale>
            <uri>/home/jgy/RMUC_simulation/src/sentry_simulation/mesh/omni/roller.stl</uri>
          </mesh>
        </geometry>
        <material>
          <script>
            <name>Gazebo/Black</name>
            <uri>file://media/materials/scripts/gazebo.material</uri>
          </script>
        </material>
      </visual>
      <pose>0 0 0 0 -0 0</pose>
      <self_collide>0</self_collide>
      <enable_wind>0</enable_wind>
      <kinematic>0</kinematic>
    </link>
    <joint name='right_roller_sw_joint' type='revolute'>
      <pose relative_to='right_wheel_link'>-0.009581 -0.009581 -0.0055 -1.5708 -0 -2.35619</pose>
      <parent>right_wheel_link</parent>
      <child>right_roller_sw_link</child>
      <axis>
        <xyz>0 0 1</xyz>
        <limit>
          <lower>-1e+16</lower>
          <upper>1e+16</upper>
        </limit>
        <dynamics>
          <spring_reference>0</spring_reference>
          <spring_stiffness>0</spring_stiffness>
        </dynamics>
      </axis>
    </joint>
    <link name='right_roller_sw_link'>
      <pose relative_to='right_roller_sw_joint'>0 0 0 0 -0 0</pose>
      <inertial>
        <pose>0 0 0 0 -0 0</pose>
        <mass>3.7948</mass>
        <inertia>
          <ixx>8.4592e-05</ixx>
          <ixy>0</ixy>
          <ixz>0</ixz>
          <iyy>8.4592e-05</iyy>
          <iyz>0</iyz>
          <izz>4.9222e-05</izz>
        </inertia>
      </inertial>
      <collision name='right_roller_sw_link_collision'>
        <pose>0 0 0 0 -0 0</pose>
        <geometry>
          <mesh>
            <scale>1 1 1</scale>
            <uri>/home/jgy/RMUC_simulation/src/sentry_simulation/mesh/omni/roller.stl</uri>
          </mesh>
        </geometry>
        <surface>
          <contact>
            <ode/>
          </contact>
          <friction>
            <ode/>
            <torsional>
              <ode/>
            </torsional>
          </friction>
          <bounce/>
        </surface>
        <max_contacts>10</max_contacts>
      </collision>
      <visual name='right_roller_sw_link_visual'>
        <pose>0 0 0 0 -0 0</pose>
        <geometry>
          <mesh>
            <scale>1 1 1</scale>
            <uri>/home/jgy/RMUC_simulation/src/sentry_simulation/mesh/omni/roller.stl</uri>
          </mesh>
        </geometry>
        <material>
          <script>
            <name>Gazebo/Black</name>
            <uri>file://media/materials/scripts/gazebo.material</uri>
          </script>
        </material>
      </visual>
      <pose>0 0 0 0 -0 0</pose>
      <self_collide>0</self_collide>
      <enable_wind>0</enable_wind>
      <kinematic>0</kinematic>
    </link>
    <joint name='right_roller_w_joint' type='revolute'>
      <pose relative_to='right_wheel_link'>-0.01355 0 0.0055 -1.5708 -0 3.14159</pose>
      <parent>right_wheel_link</parent>
      <child>right_roller_w_link</child>
      <axis>
        <xyz>0 0 1</xyz>
        <limit>
          <lower>-1e+16</lower>
          <upper>1e+16</upper>
        </limit>
        <dynamics>
          <spring_reference>0</spring_reference>
          <spring_stiffness>0</spring_stiffness>
        </dynamics>
      </axis>
    </joint>
    <link name='right_roller_w_link'>
      <pose relative_to='right_roller_w_joint'>0 0 0 0 -0 0</pose>
      <inertial>
        <pose>0 0 0 0 -0 0</pose>
        <mass>3.7948</mass>
        <inertia>
          <ixx>8.4592e-05</ixx>
          <ixy>0</ixy>
          <ixz>0</ixz>
          <iyy>8.4592e-05</iyy>
          <iyz>0</iyz>
          <izz>4.9222e-05</izz>
        </inertia>
      </inertial>
      <collision name='right_roller_w_link_collision'>
        <pose>0 0 0 0 -0 0</pose>
        <geometry>
          <mesh>
            <scale>1 1 1</scale>
            <uri>/home/jgy/RMUC_simulation/src/sentry_simulation/mesh/omni/roller.stl</uri>
          </mesh>
        </geometry>
        <surface>
          <contact>
            <ode/>
          </contact>
          <friction>
            <ode/>
            <torsional>
              <ode/>
            </torsional>
          </friction>
          <bounce/>
        </surface>
        <max_contacts>10</max_contacts>
      </collision>
      <visual name='right_roller_w_link_visual'>
        <pose>0 0 0 0 -0 0</pose>
        <geometry>
          <mesh>
            <scale>1 1 1</scale>
            <uri>/home/jgy/RMUC_simulation/src/sentry_simulation/mesh/omni/roller.stl</uri>
          </mesh>
        </geometry>
        <material>
          <script>
            <name>Gazebo/Black</name>
            <uri>file://media/materials/scripts/gazebo.material</uri>
          </script>
        </material>
      </visual>
      <pose>0 0 0 0 -0 0</pose>
      <self_collide>0</self_collide>
      <enable_wind>0</enable_wind>
      <kinematic>0</kinematic>
    </link>
    <static>0</static>
    <plugin name='gazebo_ros_control' filename='libgazebo_ros_control.so'>
      <robotNamespace>/</robotNamespace>
    </plugin>
    <plugin name='omni_plugin' filename='../../plugin/build/libmain.so'>
      <robotNamespace>/</robotNamespace>
    </plugin>
      <pose>8.30018 4.58203 0.018392 -0.005796 0.004392 -1.8399</pose>
  </model>
<sdf>
